Workbook

Sheet Critères
A1: =#REF! -> #REF!
A2: Thématique | B2: Critère | C2: Recommandation | D2: Validation
A3: IMAGES | B3: 1.1 | C3: Chaque image porteuse d’information a-t-elle une alternative textuelle ? | D3: ='P01'!$D4 -> NT
B4: 1.2 | C4: Chaque image de décoration est-elle correctement ignorée par les technologies d’assistance ? | D4: ='P01'!$D5 -> NT
B5: 1.3 | C5: Pour chaque image porteuse d'information ayant une alternative textuelle, cette alternative est-elle pertinente (hors cas particuliers) ? | D5: ='P01'!$D6 -> NT
B6: 1.4 | C6: Pour chaque image utilisée comme CAPTCHA ou comme image-test, ayant une alternative textuelle, cette alternative permet-elle d’identifier la nature et la fonction de l’image ? | D6: ='P01'!$D7 -> NT
B7: 1.5 | C7: Pour chaque image utilisée comme CAPTCHA, une solution d’accès alternatif au contenu ou à la fonction du CAPTCHA est-elle présente ? | D7: ='P01'!$D8 -> NT
B8: 1.6 | C8: Chaque image porteuse d’information a-t-elle, si nécessaire, une description détaillée ? | D8: ='P01'!$D9 -> NT
B9: 1.7 | C9: Pour chaque image porteuse d’information ayant une description détaillée, cette description est-elle pertinente ? | D9: ='P01'!$D10 -> NT
B10: 1.8 | C10: Chaque image texte porteuse d’information, en l’absence d’un mécanisme de remplacement, doit si possible être remplacée par du texte stylé. Cette règle est-elle respectée (hors cas particuliers) ? | D10: ='P01'!$D11 -> NT
B11: 1.9 | C11: Chaque légende d’image est-elle, si nécessaire, correctement reliée à l’image correspondante ? | D11: ='P01'!$D12 -> NT
A13: CADRES | B13: 2.1 | C13: Chaque cadre a-t-il un titre de cadre ? | D13: ='P01'!$D13 -> NT
B14: 2.2 | C14: Pour chaque cadre ayant un titre de cadre, ce titre de cadre est-il pertinent ? | D14: ='P01'!$D14 -> NT
A16: COULEURS | B16: 3.1 | C16: Dans chaque page web, l’information ne doit pas être donnée uniquement par la couleur. Cette règle est-elle respectée ? | D16: ='P01'!$D15 -> NT
B17: 3.2 | C17: Dans chaque page web, le contraste entre la couleur du texte et la couleur de son arrière-plan est-il suffisamment élevé (hors cas particuliers) ? | D17: ='P01'!$D16 -> NT
B18: 3.3 | C18: Dans chaque page web, les couleurs utilisées dans les composants d’interface ou les éléments graphiques porteurs d’informations sont-elles suffisamment contrastées (hors cas particuliers) ? | D18: ='P01'!$D17 -> NT
A20: MULTIMÉDIA | B20: 4.1 | C20: Chaque média temporel pré-enregistré a-t-il, si nécessaire, une transcription textuelle ou une audiodescription (hors cas particuliers) ? | D20: ='P01'!$D18 -> NT
B21: 4.2 | C21: Pour chaque média temporel pré-enregistré ayant une transcription textuelle ou une audiodescription synchronisée, celles-ci sont-elles pertinentes (hors cas particuliers) ? | D21: ='P01'!$D19 -> NT
B22: 4.3 | C22: Chaque média temporel synchronisé pré-enregistré a-t-il, si nécessaire, des sous-titres synchronisés (hors cas particuliers) ? | D22: ='P01'!$D20 -> NT
B23: 4.4 | C23: Pour chaque média temporel synchronisé pré-enregistré ayant des sous-titres synchronisés, ces sous-titres sont-ils pertinents ? | D23: ='P01'!$D21 -> NT
B24: 4.5 | C24: Chaque média temporel pré-enregistré a-t-il, si nécessaire, une audiodescription synchronisée (hors cas particuliers) ? | D24: ='P01'!$D22 -> NT
B25: 4.6 | C25: Pour chaque média temporel pré-enregistré ayant une audiodescription synchronisée, celle-ci est-elle pertinente ? | D25: ='P01'!$D23 -> NT
B26: 4.7 | C26: Chaque média temporel est-il clairement identifiable (hors cas particuliers) ? | D26: ='P01'!$D24 -> NT
B27: 4.8 | C27: Chaque média non temporel a-t-il, si nécessaire, une alternative (hors cas particuliers) ? | D27: ='P01'!$D25 -> NT
B28: 4.9 | C28: Pour chaque média non temporel ayant une alternative, cette alternative est-elle pertinente ? | D28: ='P01'!$D26 -> NT
B29: 4.10 | C29: Chaque son déclenché automatiquement est-il contrôlable par l’utilisateur ? | D29: ='P01'!$D27 -> NT
B30: 4.11 | C30: La consultation de chaque média temporel est-elle, si nécessaire, contrôlable par le clavier et tout dispositif de pointage ? | D30: ='P01'!$D28 -> NT
B31: 4.12 | C31: La consultation de chaque média non temporel est-elle contrôlable par le clavier et tout dispositif de pointage ? | D31: ='P01'!$D29 -> NT
B32: 4.13 | C32: Chaque média temporel et non temporel est-il compatible avec les technologies d’assistance (hors cas particuliers) ? | D32: ='P01'!$D30 -> NT
A34: TABLEAUX | B34: 5.1 | C34: Chaque tableau de données complexe a-t-il un résumé ? | D34: ='P01'!$D31 -> NT
B35: 5.2 | C35: Pour chaque tableau de données complexe ayant un résumé, celui-ci est-il pertinent ? | D35: ='P01'!$D32 -> NT
B36: 5.3 | C36: Pour chaque tableau de mise en forme, le contenu linéarisé reste-t-il compréhensible ? | D36: ='P01'!$D33 -> NT
B37: 5.4 | C37: Pour chaque tableau de données ayant un titre, le titre est-il correctement associé au tableau de données ? | D37: ='P01'!$D34 -> NT
B38: 5.5 | C38: Pour chaque tableau de données ayant un titre, celui-ci est-il pertinent ? | D38: ='P01'!$D35 -> NT
B39: 5.6 | C39: Pour chaque tableau de données, chaque en-tête de colonnes et chaque en-tête de lignes sont-ils correctement déclarés ? | D39: ='P01'!$D36 -> NT
B40: 5.7 | C40: Pour chaque tableau de données, la technique appropriée permettant d’associer chaque cellule avec ses en-têtes est-elle utilisée (hors cas particuliers) ? | D40: ='P01'!$D37 -> NT
B41: 5.8 | C41: Chaque tableau de mise en forme ne doit pas utiliser d’éléments propres aux tableaux de données. Cette règle est-elle respectée ? | D41: ='P01'!$D38 -> NT
A43: LIENS | B43: 6.1 | C43: Chaque lien est-il explicite (hors cas particuliers) ? | D43: ='P01'!$D39 -> NT
B44: 6.2 | C44: Dans chaque page web, chaque lien a-t-il un intitulé ? | D44: ='P01'!$D40 -> NT
A46: SCRIPTS | B46: 7.1 | C46: Chaque script est-il, si nécessaire, compatible avec les technologies d’assistance ? | D46: ='P01'!$D41 -> NT
...

Sheet BaseDeCalcul
D1: P01 | E1: P02 | F1: P03 | G1: P04 | H1: P05 | I1: P06 | J1: P07 | K1: P08 | L1: P09 | M1: P10 | N1: P11 | O1: P12 | P1: P13 | Q1: P14 | R1: P15 | S1: P16 | T1: P17 | U1: P18 | V1: P19 | W1: P20 | X1: C | Y1: NC | Z1: NA | AA1: NT | AF1: P01 | AG1: P02 | AH1: P03 | AI1: P04 | AJ1: P05 | AK1: P06 | AL1: P07 | AM1: P08 | AN1: P09 | AO1: P10 | AP1: P11 | AQ1: P12 | AR1: P13 | AS1: P14 | AT1: P15 | AU1: P16 | AV1: P17 | AW1: P18 | AX1: P19 | AY1: P20 | AZ1: TOTAL D
A3: 1 | B3: =Critères!$B3 -> 1.1 | C3: =Critères!$A3 -> IMAGES | D3: ='P01'!$D4 -> NT | E3: =#REF! -> #REF! | F3: =#REF! -> #REF! | G3: =#REF! -> #REF! | H3: =#REF! -> #REF! | I3: =#REF! -> #REF! | J3: =#REF! -> #REF! | K3: =#REF! -> #REF! | L3: =#REF! -> #REF! | ... W3: =#REF! -> #REF! | X3: =COUNTIF(D3:W3,"C") -> 0 | Y3: =COUNTIF(D3:W3,"NC") -> 0 | Z3: =COUNTIF(D3:W3,"NA") -> 0 | AA3: =COUNTIF(D3:W3,"NT") -> 1 | AB3: =IF(Y3>0,"NC",IF(X3>0,"C",IF(AA3>0,"NT","NA"))) -> NT | AC3: 1 | AD3: =Critères!$B3 -> 1.1 | AE3: =Critères!$A3 -> IMAGES | AF3: ='P01'!$E4 -> N | AG3: =#REF! -> #REF! | AH3: =#REF! -> #REF! | AI3: =#REF! -> #REF! | AJ3: =#REF! -> #REF! | AK3: =#REF! -> #REF! | AL3: =#REF! -> #REF! | AM3: =#REF! -> #REF! | AN3: =#REF! -> #REF! | ... AY3: =#REF! -> #REF! | AZ3: =COUNTIF(AF3:AY3,"D") -> 0
A4: 1 | B4: =Critères!$B4 -> 1.2 | C4: =Critères!$A3 -> IMAGES | D4: ='P01'!$D5 -> NT | E4: =#REF! -> #REF! | F4: =#REF! -> #REF! | G4: =#REF! -> #REF! | H4: =#REF! -> #REF! | I4: =#REF! -> #REF! | J4: =#REF! -> #REF! | K4: =#REF! -> #REF! | L4: =#REF! -> #REF! | ... W4: =#REF! -> #REF! | X4: =COUNTIF(D4:W4,"C") -> 0 | Y4: =COUNTIF(D4:W4,"NC") -> 0 | Z4: =COUNTIF(D4:W4,"NA") -> 0 | AA4: =COUNTIF(D4:W4,"NT") -> 1 | AB4: =IF(Y4>0,"NC",IF(X4>0,"C",IF(AA4>0,"NT","NA"))) -> NT | AC4: 1 | AD4: =Critères!$B4 -> 1.2 | AE4: =Critères!$A3 -> IMAGES | AF4: ='P01'!$E5 -> N | AG4: =#REF! -> #REF! | AH4: =#REF! -> #REF! | AI4: =#REF! -> #REF! | AJ4: =#REF! -> #REF! | AK4: =#REF! -> #REF! | AL4: =#REF! -> #REF! | AM4: =#REF! -> #REF! | AN4: =#REF! -> #REF! | ... AY4: =#REF! -> #REF! | AZ4: =COUNTIF(AF4:AY4,"D") -> 0
A5: 1 | B5: =Critères!$B5 -> 1.3 | C5: =Critères!$A3 -> IMAGES | D5: ='P01'!$D6 -> NT | E5: =#REF! -> #REF! | F5: =#REF! -> #REF! | G5: =#REF! -> #REF! | H5: =#REF! -> #REF! | I5: =#REF! -> #REF! | J5: =#REF! -> #REF! | K5: =#REF! -> #REF! | L5: =#REF! -> #REF! | ... W5: =#REF! -> #REF! | X5: =COUNTIF(D5:W5,"C") -> 0 | Y5: =COUNTIF(D5:W5,"NC") -> 0 | Z5: =COUNTIF(D5:W5,"NA") -> 0 | AA5: =COUNTIF(D5:W5,"NT") -> 1 | AB5: =IF(Y5>0,"NC",IF(X5>0,"C",IF(AA5>0,"NT","NA"))) -> NT | AC5: 1 | AD5: =Critères!$B5 -> 1.3 | AE5: =Critères!$A3 -> IMAGES | AF5: ='P01'!$E6 -> N | AG5: =#REF! -> #REF! | AH5: =#REF! -> #REF! | AI5: =#REF! -> #REF! | AJ5: =#REF! -> #REF! | AK5: =#REF! -> #REF! | AL5: =#REF! -> #REF! | AM5: =#REF! -> #REF! | AN5: =#REF! -> #REF! | ... AY5: =#REF! -> #REF! | AZ5: =COUNTIF(AF5:AY5,"D") -> 0
A6: 1 | B6: =Critères!$B6 -> 1.4 | C6: =Critères!$A3 -> IMAGES | D6: ='P01'!$D7 -> NT | E6: =#REF! -> #REF! | F6: =#REF! -> #REF! | G6: =#REF! -> #REF! | H6: =#REF! -> #REF! | I6: =#REF! -> #REF! | J6: =#REF! -> #REF! | K6: =#REF! -> #REF! | L6: =#REF! -> #REF! | ... W6: =#REF! -> #REF! | X6: =COUNTIF(D6:W6,"C") -> 0 | Y6: =COUNTIF(D6:W6,"NC") -> 0 | Z6: =COUNTIF(D6:W6,"NA") -> 0 | AA6: =COUNTIF(D6:W6,"NT") -> 1 | AB6: =IF(Y6>0,"NC",IF(X6>0,"C",IF(AA6>0,"NT","NA"))) -> NT | AC6: 1 | AD6: =Critères!$B6 -> 1.4 | AE6: =Critères!$A3 -> IMAGES | AF6: ='P01'!$E7 -> N | AG6: =#REF! -> #REF! | AH6: =#REF! -> #REF! | AI6: =#REF! -> #REF! | AJ6: =#REF! -> #REF! | AK6: =#REF! -> #REF! | AL6: =#REF! -> #REF! | AM6: =#REF! -> #REF! | AN6: =#REF! -> #REF! | ... AY6: =#REF! -> #REF! | AZ6: =COUNTIF(AF6:AY6,"D") -> 0
A7: 1 | B7: =Critères!$B7 -> 1.5 | C7: =Critères!$A3 -> IMAGES | D7: ='P01'!$D8 -> NT | E7: =#REF! -> #REF! | F7: =#REF! -> #REF! | G7: =#REF! -> #REF! | H7: =#REF! -> #REF! | I7: =#REF! -> #REF! | J7: =#REF! -> #REF! | K7: =#REF! -> #REF! | L7: =#REF! -> #REF! | ... W7: =#REF! -> #REF! | X7: =COUNTIF(D7:W7,"C") -> 0 | Y7: =COUNTIF(D7:W7,"NC") -> 0 | Z7: =COUNTIF(D7:W7,"NA") -> 0 | AA7: =COUNTIF(D7:W7,"NT") -> 1 | AB7: =IF(Y7>0,"NC",IF(X7>0,"C",IF(AA7>0,"NT","NA"))) -> NT | AC7: 1 | AD7: =Critères!$B7 -> 1.5 | AE7: =Critères!$A3 -> IMAGES | AF7: ='P01'!$E8 -> N | AG7: =#REF! -> #REF! | AH7: =#REF! -> #REF! | AI7: =#REF! -> #REF! | AJ7: =#REF! -> #REF! | AK7: =#REF! -> #REF! | AL7: =#REF! -> #REF! | AM7: =#REF! -> #REF! | AN7: =#REF! -> #REF! | ... AY7: =#REF! -> #REF! | AZ7: =COUNTIF(AF7:AY7,"D") -> 0
A8: 1 | B8: =Critères!$B8 -> 1.6 | C8: =Critères!$A3 -> IMAGES | D8: ='P01'!$D9 -> NT | E8: =#REF! -> #REF! | F8: =#REF! -> #REF! | G8: =#REF! -> #REF! | H8: =#REF! -> #REF! | I8: =#REF! -> #REF! | J8: =#REF! -> #REF! | K8: =#REF! -> #REF! | L8: =#REF! -> #REF! | ... W8: =#REF! -> #REF! | X8: =COUNTIF(D8:W8,"C") -> 0 | Y8: =COUNTIF(D8:W8,"NC") -> 0 | Z8: =COUNTIF(D8:W8,"NA") -> 0 | AA8: =COUNTIF(D8:W8,"NT") -> 1 | AB8: =IF(Y8>0,"NC",IF(X8>0,"C",IF(AA8>0,"NT","NA"))) -> NT | AC8: 1 | AD8: =Critères!$B8 -> 1.6 | AE8: =Critères!$A3 -> IMAGES | AF8: ='P01'!$E9 -> N | AG8: =#REF! -> #REF! | AH8: =#REF! -> #REF! | AI8: =#REF! -> #REF! | AJ8: =#REF! -> #REF! | AK8: =#REF! -> #REF! | AL8: =#REF! -> #REF! | AM8: =#REF! -> #REF! | AN8: =#REF! -> #REF! | ... AY8: =#REF! -> #REF! | AZ8: =COUNTIF(AF8:AY8,"D") -> 0
A9: 1 | B9: =Critères!$B9 -> 1.7 | C9: =Critères!$A3 -> IMAGES | D9: ='P01'!$D10 -> NT | E9: =#REF! -> #REF! | F9: =#REF! -> #REF! | G9: =#REF! -> #REF! | H9: =#REF! -> #REF! | I9: =#REF! -> #REF! | J9: =#REF! -> #REF! | K9: =#REF! -> #REF! | L9: =#REF! -> #REF! | ... W9: =#REF! -> #REF! | X9: =COUNTIF(D9:W9,"C") -> 0 | Y9: =COUNTIF(D9:W9,"NC") -> 0 | Z9: =COUNTIF(D9:W9,"NA") -> 0 | AA9: =COUNTIF(D9:W9,"NT") -> 1 | AB9: =IF(Y9>0,"NC",IF(X9>0,"C",IF(AA9>0,"NT","NA"))) -> NT | AC9: 1 | AD9: =Critères!$B9 -> 1.7 | AE9: =Critères!$A3 -> IMAGES | AF9: ='P01'!$E10 -> N | AG9: =#REF! -> #REF! | AH9: =#REF! -> #REF! | AI9: =#REF! -> #REF! | AJ9: =#REF! -> #REF! | AK9: =#REF! -> #REF! | AL9: =#REF! -> #REF! | AM9: =#REF! -> #REF! | AN9: =#REF! -> #REF! | ... AY9: =#REF! -> #REF! | AZ9: =COUNTIF(AF9:AY9,"D") -> 0
A10: 1 | B10: =Critères!$B10 -> 1.8 | C10: =Critères!$A3 -> IMAGES | D10: ='P01'!$D11 -> NT | E10: =#REF! -> #REF! | F10: =#REF! -> #REF! | G10: =#REF! -> #REF! | H10: =#REF! -> #REF! | I10: =#REF! -> #REF! | J10: =#REF! -> #REF! | K10: =#REF! -> #REF! | L10: =#REF! -> #REF! | ... W10: =#REF! -> #REF! | X10: =COUNTIF(D10:W10,"C") -> 0 | Y10: =COUNTIF(D10:W10,"NC") -> 0 | Z10: =COUNTIF(D10:W10,"NA") -> 0 | AA10: =COUNTIF(D10:W10,"NT") -> 1 | AB10: =IF(Y10>0,"NC",IF(X10>0,"C",IF(AA10>0,"NT","NA"))) -> NT | AC10: 1 | AD10: =Critères!$B10 -> 1.8 | AE10: =Critères!$A3 -> IMAGES | AF10: ='P01'!$E11 -> N | AG10: =#REF! -> #REF! | AH10: =#REF! -> #REF! | AI10: =#REF! -> #REF! | AJ10: =#REF! -> #REF! | AK10: =#REF! -> #REF! | AL10: =#REF! -> #REF! | AM10: =#REF! -> #REF! | AN10: =#REF! -> #REF! | ... AY10: =#REF! -> #REF! | AZ10: =COUNTIF(AF10:AY10,"D") -> 0
A11: 1 | B11: =Critères!$B11 -> 1.9 | C11: =Critères!$A3 -> IMAGES | D11: ='P01'!$D12 -> NT | E11: =#REF! -> #REF! | F11: =#REF! -> #REF! | G11: =#REF! -> #REF! | H11: =#REF! -> #REF! | I11: =#REF! -> #REF! | J11: =#REF! -> #REF! | K11: =#REF! -> #REF! | L11: =#REF! -> #REF! | ... W11: =#REF! -> #REF! | X11: =COUNTIF(D11:W11,"C") -> 0 | Y11: =COUNTIF(D11:W11,"NC") -> 0 | Z11: =COUNTIF(D11:W11,"NA") -> 0 | AA11: =COUNTIF(D11:W11,"NT") -> 1 | AB11: =IF(Y11>0,"NC",IF(X11>0,"C",IF(AA11>0,"NT","NA"))) -> NT | AC11: 1 | AD11: =Critères!$B11 -> 1.9 | AE11: =Critères!$A3 -> IMAGES | AF11: ='P01'!$E12 -> N | AG11: =#REF! -> #REF! | AH11: =#REF! -> #REF! | AI11: =#REF! -> #REF! | AJ11: =#REF! -> #REF! | AK11: =#REF! -> #REF! | AL11: =#REF! -> #REF! | AM11: =#REF! -> #REF! | AN11: =#REF! -> #REF! | ... AY11: =#REF! -> #REF! | AZ11: =COUNTIF(AF11:AY11,"D") -> 0
X12: =SUM(X3:X11) -> 0 | Y12: =SUM(Y3:Y11) -> 0 | Z12: =SUM(Z3:Z11) -> 0 | AA12: =SUM(AA3:AA11) -> 9 | AZ12: =SUM(AZ1:AZ11) -> 0
A13: 2 | B13: =Critères!$B13 -> 2.1 | C13: =Critères!$A13 -> CADRES | D13: ='P01'!$D13 -> NT | E13: =#REF! -> #REF! | F13: =#REF! -> #REF! | G13: =#REF! -> #REF! | H13: =#REF! -> #REF! | I13: =#REF! -> #REF! | J13: =#REF! -> #REF! | K13: =#REF! -> #REF! | L13: =#REF! -> #REF! | ... W13: =#REF! -> #REF! | X13: =COUNTIF(D13:W13,"C") -> 0 | Y13: =COUNTIF(D13:W13,"NC") -> 0 | Z13: =COUNTIF(D13:W13,"NA") -> 0 | AA13: =COUNTIF(D13:W13,"NT") -> 1 | AB13: =IF(Y13>0,"NC",IF(X13>0,"C",IF(AA13>0,"NT","NA"))) -> NT | AC13: 2 | AD13: =Critères!$B13 -> 2.1 | AE13: =Critères!$A13 -> CADRES | AF13: ='P01'!$E13 -> N | AG13: =#REF! -> #REF! | AH13: =#REF! -> #REF! | AI13: =#REF! -> #REF! | AJ13: =#REF! -> #REF! | AK13: =#REF! -> #REF! | AL13: =#REF! -> #REF! | AM13: =#REF! -> #REF! | AN13: =#REF! -> #REF! | ... AY13: =#REF! -> #REF! | AZ13: =COUNTIF(AF13:AY13,"D") -> 0
A14: 2 | B14: =Critères!$B14 -> 2.2 | C14: =Critères!$A13 -> CADRES | D14: ='P01'!$D14 -> NT | E14: =#REF! -> #REF! | F14: =#REF! -> #REF! | G14: =#REF! -> #REF! | H14: =#REF! -> #REF! | I14: =#REF! -> #REF! | J14: =#REF! -> #REF! | K14: =#REF! -> #REF! | L14: =#REF! -> #REF! | ... W14: =#REF! -> #REF! | X14: =COUNTIF(D14:W14,"C") -> 0 | Y14: =COUNTIF(D14:W14,"NC") -> 0 | Z14: =COUNTIF(D14:W14,"NA") -> 0 | AA14: =COUNTIF(D14:W14,"NT") -> 1 | AB14: =IF(Y14>0,"NC",IF(X14>0,"C",IF(AA14>0,"NT","NA"))) -> NT | AC14: 2 | AD14: =Critères!$B14 -> 2.2 | AE14: =Critères!$A13 -> CADRES | AF14: ='P01'!$E14 -> N | AG14: =#REF! -> #REF! | AH14: =#REF! -> #REF! | AI14: =#REF! -> #REF! | AJ14: =#REF! -> #REF! | AK14: =#REF! -> #REF! | AL14: =#REF! -> #REF! | AM14: =#REF! -> #REF! | AN14: =#REF! -> #REF! | ... AY14: =#REF! -> #REF! | AZ14: =COUNTIF(AF14:AY14,"D") -> 0
X15: =SUM(X13:X14) -> 0 | Y15: =SUM(Y13:Y14) -> 0 | Z15: =SUM(Z13:Z14) -> 0 | AA15: =SUM(AA13:AA14) -> 2 | AZ15: =SUM(AZ13:AZ14) -> 0
A16: 3 | B16: =Critères!$B16 -> 3.1 | C16: =Critères!$A16 -> COULEURS | D16: ='P01'!$D15 -> NT | E16: =#REF! -> #REF! | F16: =#REF! -> #REF! | G16: =#REF! -> #REF! | H16: =#REF! -> #REF! | I16: =#REF! -> #REF! | J16: =#REF! -> #REF! | K16: =#REF! -> #REF! | L16: =#REF! -> #REF! | ... W16: =#REF! -> #REF! | X16: =COUNTIF(D16:W16,"C") -> 0 | Y16: =COUNTIF(D16:W16,"NC") -> 0 | Z16: =COUNTIF(D16:W16,"NA") -> 0 | AA16: =COUNTIF(D16:W16,"NT") -> 1 | AB16: =IF(Y16>0,"NC",IF(X16>0,"C",IF(AA16>0,"NT","NA"))) -> NT | AC16: 3 | AD16: =Critères!$B16 -> 3.1 | AE16: =Critères!$A16 -> COULEURS | AF16: ='P01'!$E15 -> N | AG16: =#REF! -> #REF! | AH16: =#REF! -> #REF! | AI16: =#REF! -> #REF! | AJ16: =#REF! -> #REF! | AK16: =#REF! -> #REF! | AL16: =#REF! -> #REF! | AM16: =#REF! -> #REF! | AN16: =#REF! -> #REF! | ... AY16: =#REF! -> #REF! | AZ16: =COUNTIF(AF16:AY16,"D") -> 0
A17: 3 | B17: =Critères!$B17 -> 3.2 | C17: =Critères!$A16 -> COULEURS | D17: ='P01'!$D16 -> NT | E17: =#REF! -> #REF! | F17: =#REF! -> #REF! | G17: =#REF! -> #REF! | H17: =#REF! -> #REF! | I17: =#REF! -> #REF! | J17: =#REF! -> #REF! | K17: =#REF! -> #REF! | L17: =#REF! -> #REF! | ... W17: =#REF! -> #REF! | X17: =COUNTIF(D17:W17,"C") -> 0 | Y17: =COUNTIF(D17:W17,"NC") -> 0 | Z17: =COUNTIF(D17:W17,"NA") -> 0 | AA17: =COUNTIF(D17:W17,"NT") -> 1 | AB17: =IF(Y17>0,"NC",IF(X17>0,"C",IF(AA17>0,"NT","NA"))) -> NT | AC17: 3 | AD17: =Critères!$B17 -> 3.2 | AE17: =Critères!$A16 -> COULEURS | AF17: ='P01'!$E16 -> N | AG17: =#REF! -> #REF! | AH17: =#REF! -> #REF! | AI17: =#REF! -> #REF! | AJ17: =#REF! -> #REF! | AK17: =#REF! -> #REF! | AL17: =#REF! -> #REF! | AM17: =#REF! -> #REF! | AN17: =#REF! -> #REF! | ... AY17: =#REF! -> #REF! | AZ17: =COUNTIF(AF17:AY17,"D") -> 0
A18: 3 | B18: =Critères!$B18 -> 3.3 | C18: =Critères!$A16 -> COULEURS | D18: ='P01'!$D17 -> NT | E18: =#REF! -> #REF! | F18: =#REF! -> #REF! | G18: =#REF! -> #REF! | H18: =#REF! -> #REF! | I18: =#REF! -> #REF! | J18: =#REF! -> #REF! | K18: =#REF! -> #REF! | L18: =#REF! -> #REF! | ... W18: =#REF! -> #REF! | X18: =COUNTIF(D18:W18,"C") -> 0 | Y18: =COUNTIF(D18:W18,"NC") -> 0 | Z18: =COUNTIF(D18:W18,"NA") -> 0 | AA18: =COUNTIF(D18:W18,"NT") -> 1 | AB18: =IF(Y18>0,"NC",IF(X18>0,"C",IF(AA18>0,"NT","NA"))) -> NT | AC18: 3 | AD18: =Critères!$B18 -> 3.3 | AE18: =Critères!$A16 -> COULEURS | AF18: ='P01'!$E17 -> N | AG18: =#REF! -> #REF! | AH18: =#REF! -> #REF! | AI18: =#REF! -> #REF! | AJ18: =#REF! -> #REF! | AK18: =#REF! -> #REF! | AL18: =#REF! -> #REF! | AM18: =#REF! -> #REF! | AN18: =#REF! -> #REF! | ... AY18: =#REF! -> #REF! | AZ18: =COUNTIF(AF18:AY18,"D") -> 0
X19: =SUM(X16:X18) -> 0 | Y19: =SUM(Y16:Y18) -> 0 | Z19: =SUM(Z16:Z18) -> 0 | AA19: =SUM(AA16:AA18) -> 3 | AZ19: =SUM(AZ16:AZ18) -> 0
A20: 4 | B20: =Critères!$B20 -> 4.1 | C20: =Critères!$A20 -> MULTIMÉDIA | D20: ='P01'!$D18 -> NT | E20: =#REF! -> #REF! | F20: =#REF! -> #REF! | G20: =#REF! -> #REF! | H20: =#REF! -> #REF! | I20: =#REF! -> #REF! | J20: =#REF! -> #REF! | K20: =#REF! -> #REF! | L20: =#REF! -> #REF! | ... W20: =#REF! -> #REF! | X20: =COUNTIF(D20:W20,"C") -> 0 | Y20: =COUNTIF(D20:W20,"NC") -> 0 | Z20: =COUNTIF(D20:W20,"NA") -> 0 | AA20: =COUNTIF(D20:W20,"NT") -> 1 | AB20: =IF(Y20>0,"NC",IF(X20>0,"C",IF(AA20>0,"NT","NA"))) -> NT | AC20: 4 | AD20: =Critères!$B20 -> 4.1 | AE20: =Critères!$A20 -> MULTIMÉDIA | AF20: ='P01'!$E18 -> N | AG20: =#REF! -> #REF! | AH20: =#REF! -> #REF! | AI20: =#REF! -> #REF! | AJ20: =#REF! -> #REF! | AK20: =#REF! -> #REF! | AL20: =#REF! -> #REF! | AM20: =#REF! -> #REF! | AN20: =#REF! -> #REF! | ... AY20: =#REF! -> #REF! | AZ20: =COUNTIF(AF20:AY20,"D") -> 0
A21: 4 | B21: =Critères!$B21 -> 4.2 | C21: =Critères!$A20 -> MULTIMÉDIA | D21: ='P01'!$D19 -> NT | E21: =#REF! -> #REF! | F21: =#REF! -> #REF! | G21: =#REF! -> #REF! | H21: =#REF! -> #REF! | I21: =#REF! -> #REF! | J21: =#REF! -> #REF! | K21: =#REF! -> #REF! | L21: =#REF! -> #REF! | ... W21: =#REF! -> #REF! | X21: =COUNTIF(D21:W21,"C") -> 0 | Y21: =COUNTIF(D21:W21,"NC") -> 0 | Z21: =COUNTIF(D21:W21,"NA") -> 0 | AA21: =COUNTIF(D21:W21,"NT") -> 1 | AB21: =IF(Y21>0,"NC",IF(X21>0,"C",IF(AA21>0,"NT","NA"))) -> NT | AC21: 4 | AD21: =Critères!$B21 -> 4.2 | AE21: =Critères!$A20 -> MULTIMÉDIA | AF21: ='P01'!$E19 -> N | AG21: =#REF! -> #REF! | AH21: =#REF! -> #REF! | AI21: =#REF! -> #REF! | AJ21: =#REF! -> #REF! | AK21: =#REF! -> #REF! | AL21: =#REF! -> #REF! | AM21: =#REF! -> #REF! | AN21: =#REF! -> #REF! | ... AY21: =#REF! -> #REF! | AZ21: =COUNTIF(AF21:AY21,"D") -> 0
A22: 4 | B22: =Critères!$B22 -> 4.3 | C22: =Critères!$A20 -> MULTIMÉDIA | D22: ='P01'!$D20 -> NT | E22: =#REF! -> #REF! | F22: =#REF! -> #REF! | G22: =#REF! -> #REF! | H22: =#REF! -> #REF! | I22: =#REF! -> #REF! | J22: =#REF! -> #REF! | K22: =#REF! -> #REF! | L22: =#REF! -> #REF! | ... W22: =#REF! -> #REF! | X22: =COUNTIF(D22:W22,"C") -> 0 | Y22: =COUNTIF(D22:W22,"NC") -> 0 | Z22: =COUNTIF(D22:W22,"NA") -> 0 | AA22: =COUNTIF(D22:W22,"NT") -> 1 | AB22: =IF(Y22>0,"NC",IF(X22>0,"C",IF(AA22>0,"NT","NA"))) -> NT | AC22: 4 | AD22: =Critères!$B22 -> 4.3 | AE22: =Critères!$A20 -> MULTIMÉDIA | AF22: ='P01'!$E20 -> N | AG22: =#REF! -> #REF! | AH22: =#REF! -> #REF! | AI22: =#REF! -> #REF! | AJ22: =#REF! -> #REF! | AK22: =#REF! -> #REF! | AL22: =#REF! -> #REF! | AM22: =#REF! -> #REF! | AN22: =#REF! -> #REF! | ... AY22: =#REF! -> #REF! | AZ22: =COUNTIF(AF22:AY22,"D") -> 0
A23: 4 | B23: =Critères!$B23 -> 4.4 | C23: =Critères!$A20 -> MULTIMÉDIA | D23: ='P01'!$D21 -> NT | E23: =#REF! -> #REF! | F23: =#REF! -> #REF! | G23: =#REF! -> #REF! | H23: =#REF! -> #REF! | I23: =#REF! -> #REF! | J23: =#REF! -> #REF! | K23: =#REF! -> #REF! | L23: =#REF! -> #REF! | ... W23: =#REF! -> #REF! | X23: =COUNTIF(D23:W23,"C") -> 0 | Y23: =COUNTIF(D23:W23,"NC") -> 0 | Z23: =COUNTIF(D23:W23,"NA") -> 0 | AA23: =COUNTIF(D23:W23,"NT") -> 1 | AB23: =IF(Y23>0,"NC",IF(X23>0,"C",IF(AA23>0,"NT","NA"))) -> NT | AC23: 4 | AD23: =Critères!$B23 -> 4.4 | AE23: =Critères!$A20 -> MULTIMÉDIA | AF23: ='P01'!$E21 -> N | AG23: =#REF! -> #REF! | AH23: =#REF! -> #REF! | AI23: =#REF! -> #REF! | AJ23: =#REF! -> #REF! | AK23: =#REF! -> #REF! | AL23: =#REF! -> #REF! | AM23: =#REF! -> #REF! | AN23: =#REF! -> #REF! | ... AY23: =#REF! -> #REF! | AZ23: =COUNTIF(AF23:AY23,"D") -> 0
A24: 4 | B24: =Critères!$B24 -> 4.5 | C24: =Critères!$A20 -> MULTIMÉDIA | D24: ='P01'!$D22 -> NT | E24: =#REF! -> #REF! | F24: =#REF! -> #REF! | G24: =#REF! -> #REF! | H24: =#REF! -> #REF! | I24: =#REF! -> #REF! | J24: =#REF! -> #REF! | K24: =#REF! -> #REF! | L24: =#REF! -> #REF! | ... W24: =#REF! -> #REF! | X24: =COUNTIF(D24:W24,"C") -> 0 | Y24: =COUNTIF(D24:W24,"NC") -> 0 | Z24: =COUNTIF(D24:W24,"NA") -> 0 | AA24: =COUNTIF(D24:W24,"NT") -> 1 | AB24: =IF(Y24>0,"NC",IF(X24>0,"C",IF(AA24>0,"NT","NA"))) -> NT | AC24: 4 | AD24: =Critères!$B24 -> 4.5 | AE24: =Critères!$A20 -> MULTIMÉDIA | AF24: ='P01'!$E22 -> N | AG24: =#REF! -> #REF! | AH24: =#REF! -> #REF! | AI24: =#REF! -> #REF! | AJ24: =#REF! -> #REF! | AK24: =#REF! -> #REF! | AL24: =#REF! -> #REF! | AM24: =#REF! -> #REF! | AN24: =#REF! -> #REF! | ... AY24: =#REF! -> #REF! | AZ24: =COUNTIF(AF24:AY24,"D") -> 0
A25: 4 | B25: =Critères!$B25 -> 4.6 | C25: =Critères!$A20 -> MULTIMÉDIA | D25: ='P01'!$D23 -> NT | E25: =#REF! -> #REF! | F25: =#REF! -> #REF! | G25: =#REF! -> #REF! | H25: =#REF! -> #REF! | I25: =#REF! -> #REF! | J25: =#REF! -> #REF! | K25: =#REF! -> #REF! | L25: =#REF! -> #REF! | ... W25: =#REF! -> #REF! | X25: =COUNTIF(D25:W25,"C") -> 0 | Y25: =COUNTIF(D25:W25,"NC") -> 0 | Z25: =COUNTIF(D25:W25,"NA") -> 0 | AA25: =COUNTIF(D25:W25,"NT") -> 1 | AB25: =IF(Y25>0,"NC",IF(X25>0,"C",IF(AA25>0,"NT","NA"))) -> NT | AC25: 4 | AD25: =Critères!$B25 -> 4.6 | AE25: =Critères!$A20 -> MULTIMÉDIA | AF25: ='P01'!$E23 -> N | AG25: =#REF! -> #REF! | AH25: =#REF! -> #REF! | AI25: =#REF! -> #REF! | AJ25: =#REF! -> #REF! | AK25: =#REF! -> #REF! | AL25: =#REF! -> #REF! | AM25: =#REF! -> #REF! | AN25: =#REF! -> #REF! | ... AY25: =#REF! -> #REF! | AZ25: =COUNTIF(AF25:AY25,"D") -> 0
A26: 4 | B26: =Critères!$B26 -> 4.7 | C26: =Critères!$A20 -> MULTIMÉDIA | D26: ='P01'!$D24 -> NT | E26: =#REF! -> #REF! | F26: =#REF! -> #REF! | G26: =#REF! -> #REF! | H26: =#REF! -> #REF! | I26: =#REF! -> #REF! | J26: =#REF! -> #REF! | K26: =#REF! -> #REF! | L26: =#REF! -> #REF! | ... W26: =#REF! -> #REF! | X26: =COUNTIF(D26:W26,"C") -> 0 | Y26: =COUNTIF(D26:W26,"NC") -> 0 | Z26: =COUNTIF(D26:W26,"NA") -> 0 | AA26: =COUNTIF(D26:W26,"NT") -> 1 | AB26: =IF(Y26>0,"NC",IF(X26>0,"C",IF(AA26>0,"NT","NA"))) -> NT | AC26: 4 | AD26: =Critères!$B26 -> 4.7 | AE26: =Critères!$A20 -> MULTIMÉDIA | AF26: ='P01'!$E24 -> N | AG26: =#REF! -> #REF! | AH26: =#REF! -> #REF! | AI26: =#REF! -> #REF! | AJ26: =#REF! -> #REF! | AK26: =#REF! -> #REF! | AL26: =#REF! -> #REF! | AM26: =#REF! -> #REF! | AN26: =#REF! -> #REF! | ... AY26: =#REF! -> #REF! | AZ26: =COUNTIF(AF26:AY26,"D") -> 0
A27: 4 | B27: =Critères!$B27 -> 4.8 | C27: =Critères!$A20 -> MULTIMÉDIA | D27: ='P01'!$D25 -> NT | E27: =#REF! -> #REF! | F27: =#REF! -> #REF! | G27: =#REF! -> #REF! | H27: =#REF! -> #REF! | I27: =#REF! -> #REF! | J27: =#REF! -> #REF! | K27: =#REF! -> #REF! | L27: =#REF! -> #REF! | ... W27: =#REF! -> #REF! | X27: =COUNTIF(D27:W27,"C") -> 0 | Y27: =COUNTIF(D27:W27,"NC") -> 0 | Z27: =COUNTIF(D27:W27,"NA") -> 0 | AA27: =COUNTIF(D27:W27,"NT") -> 1 | AB27: =IF(Y27>0,"NC",IF(X27>0,"C",IF(AA27>0,"NT","NA"))) -> NT | AC27: 4 | AD27: =Critères!$B27 -> 4.8 | AE27: =Critères!$A20 -> MULTIMÉDIA | AF27: ='P01'!$E25 -> N | AG27: =#REF! -> #REF! | AH27: =#REF! -> #REF! | AI27: =#REF! -> #REF! | AJ27: =#REF! -> #REF! | AK27: =#REF! -> #REF! | AL27: =#REF! -> #REF! | AM27: =#REF! -> #REF! | AN27: =#REF! -> #REF! | ... AY27: =#REF! -> #REF! | AZ27: =COUNTIF(AF27:AY27,"D") -> 0
A28: 4 | B28: =Critères!$B28 -> 4.9 | C28: =Critères!$A20 -> MULTIMÉDIA | D28: ='P01'!$D26 -> NT | E28: =#REF! -> #REF! | F28: =#REF! -> #REF! | G28: =#REF! -> #REF! | H28: =#REF! -> #REF! | I28: =#REF! -> #REF! | J28: =#REF! -> #REF! | K28: =#REF! -> #REF! | L28: =#REF! -> #REF! | ... W28: =#REF! -> #REF! | X28: =COUNTIF(D28:W28,"C") -> 0 | Y28: =COUNTIF(D28:W28,"NC") -> 0 | Z28: =COUNTIF(D28:W28,"NA") -> 0 | AA28: =COUNTIF(D28:W28,"NT") -> 1 | AB28: =IF(Y28>0,"NC",IF(X28>0,"C",IF(AA28>0,"NT","NA"))) -> NT | AC28: 4 | AD28: =Critères!$B28 -> 4.9 | AE28: =Critères!$A20 -> MULTIMÉDIA | AF28: ='P01'!$E26 -> N | AG28: =#REF! -> #REF! | AH28: =#REF! -> #REF! | AI28: =#REF! -> #REF! | AJ28: =#REF! -> #REF! | AK28: =#REF! -> #REF! | AL28: =#REF! -> #REF! | AM28: =#REF! -> #REF! | AN28: =#REF! -> #REF! | ... AY28: =#REF! -> #REF! | AZ28: =COUNTIF(AF28:AY28,"D") -> 0
A29: 4 | B29: =Critères!$B29 -> 4.10 | C29: =Critères!$A20 -> MULTIMÉDIA | D29: ='P01'!$D27 -> NT | E29: =#REF! -> #REF! | F29: =#REF! -> #REF! | G29: =#REF! -> #REF! | H29: =#REF! -> #REF! | I29: =#REF! -> #REF! | J29: =#REF! -> #REF! | K29: =#REF! -> #REF! | L29: =#REF! -> #REF! | ... W29: =#REF! -> #REF! | X29: =COUNTIF(D29:W29,"C") -> 0 | Y29: =COUNTIF(D29:W29,"NC") -> 0 | Z29: =COUNTIF(D29:W29,"NA") -> 0 | AA29: =COUNTIF(D29:W29,"NT") -> 1 | AB29: =IF(Y29>0,"NC",IF(X29>0,"C",IF(AA29>0,"NT","NA"))) -> NT | AC29: 4 | AD29: =Critères!$B29 -> 4.10 | AE29: =Critères!$A20 -> MULTIMÉDIA | AF29: ='P01'!$E27 -> N | AG29: =#REF! -> #REF! | AH29: =#REF! -> #REF! | AI29: =#REF! -> #REF! | AJ29: =#REF! -> #REF! | AK29: =#REF! -> #REF! | AL29: =#REF! -> #REF! | AM29: =#REF! -> #REF! | AN29: =#REF! -> #REF! | ... AY29: =#REF! -> #REF! | AZ29: =COUNTIF(AF29:AY29,"D") -> 0
A30: 4 | B30: =Critères!$B30 -> 4.11 | C30: =Critères!$A20 -> MULTIMÉDIA | D30: ='P01'!$D28 -> NT | E30: =#REF! -> #REF! | F30: =#REF! -> #REF! | G30: =#REF! -> #REF! | H30: =#REF! -> #REF! | I30: =#REF! -> #REF! | J30: =#REF! -> #REF! | K30: =#REF! -> #REF! | L30: =#REF! -> #REF! | ... W30: =#REF! -> #REF! | X30: =COUNTIF(D30:W30,"C") -> 0 | Y30: =COUNTIF(D30:W30,"NC") -> 0 | Z30: =COUNTIF(D30:W30,"NA") -> 0 | AA30: =COUNTIF(D30:W30,"NT") -> 1 | AB30: =IF(Y30>0,"NC",IF(X30>0,"C",IF(AA30>0,"NT","NA"))) -> NT | AC30: 4 | AD30: =Critères!$B30 -> 4.11 | AE30: =Critères!$A20 -> MULTIMÉDIA | AF30: ='P01'!$E28 -> N | AG30: =#REF! -> #REF! | AH30: =#REF! -> #REF! | AI30: =#REF! -> #REF! | AJ30: =#REF! -> #REF! | AK30: =#REF! -> #REF! | AL30: =#REF! -> #REF! | AM30: =#REF! -> #REF! | AN30: =#REF! -> #REF! | ... AY30: =#REF! -> #REF! | AZ30: =COUNTIF(AF30:AY30,"D") -> 0
A31: 4 | B31: =Critères!$B31 -> 4.12 | C31: =Critères!$A20 -> MULTIMÉDIA | D31: ='P01'!$D29 -> NT | E31: =#REF! -> #REF! | F31: =#REF! -> #REF! | G31: =#REF! -> #REF! | H31: =#REF! -> #REF! | I31: =#REF! -> #REF! | J31: =#REF! -> #REF! | K31: =#REF! -> #REF! | L31: =#REF! -> #REF! | ... W31: =#REF! -> #REF! | X31: =COUNTIF(D31:W31,"C") -> 0 | Y31: =COUNTIF(D31:W31,"NC") -> 0 | Z31: =COUNTIF(D31:W31,"NA") -> 0 | AA31: =COUNTIF(D31:W31,"NT") -> 1 | AB31: =IF(Y31>0,"NC",IF(X31>0,"C",IF(AA31>0,"NT","NA"))) -> NT | AC31: 4 | AD31: =Critères!$B31 -> 4.12 | AE31: =Critères!$A20 -> MULTIMÉDIA | AF31: ='P01'!$E29 -> N | AG31: =#REF! -> #REF! | AH31: =#REF! -> #REF! | AI31: =#REF! -> #REF! | AJ31: =#REF! -> #REF! | AK31: =#REF! -> #REF! | AL31: =#REF! -> #REF! | AM31: =#REF! -> #REF! | AN31: =#REF! -> #REF! | ... AY31: =#REF! -> #REF! | AZ31: =COUNTIF(AF31:AY31,"D") -> 0
A32: 4 | B32: =Critères!$B32 -> 4.13 | C32: =Critères!$A20 -> MULTIMÉDIA | D32: ='P01'!$D30 -> NT | E32: =#REF! -> #REF! | F32: =#REF! -> #REF! | G32: =#REF! -> #REF! | H32: =#REF! -> #REF! | I32: =#REF! -> #REF! | J32: =#REF! -> #REF! | K32: =#REF! -> #REF! | L32: =#REF! -> #REF! | ... W32: =#REF! -> #REF! | X32: =COUNTIF(D32:W32,"C") -> 0 | Y32: =COUNTIF(D32:W32,"NC") -> 0 | Z32: =COUNTIF(D32:W32,"NA") -> 0 | AA32: =COUNTIF(D32:W32,"NT") -> 1 | AB32: =IF(Y32>0,"NC",IF(X32>0,"C",IF(AA32>0,"NT","NA"))) -> NT | AC32: 4 | AD32: =Critères!$B32 -> 4.13 | AE32: =Critères!$A20 -> MULTIMÉDIA | AF32: ='P01'!$E30 -> N | AG32: =#REF! -> #REF! | AH32: =#REF! -> #REF! | AI32: =#REF! -> #REF! | AJ32: =#REF! -> #REF! | AK32: =#REF! -> #REF! | AL32: =#REF! -> #REF! | AM32: =#REF! -> #REF! | AN32: =#REF! -> #REF! | ... AY32: =#REF! -> #REF! | AZ32: =COUNTIF(AF32:AY32,"D") -> 0
X33: =SUM(X20:X32) -> 0 | Y33: =SUM(Y20:Y32) -> 0 | Z33: =SUM(Z20:Z32) -> 0 | AA33: =SUM(AA20:AA32) -> 13 | AZ33: =SUM(AZ20:AZ32) -> 0
A34: 5 | B34: =Critères!$B34 -> 5.1 | C34: =Critères!$A34 -> TABLEAUX | D34: ='P01'!$D31 -> NT | E34: =#REF! -> #REF! | F34: =#REF! -> #REF! | G34: =#REF! -> #REF! | H34: =#REF! -> #REF! | I34: =#REF! -> #REF! | J34: =#REF! -> #REF! | K34: =#REF! -> #REF! | L34: =#REF! -> #REF! | ... W34: =#REF! -> #REF! | X34: =COUNTIF(D34:W34,"C") -> 0 | Y34: =COUNTIF(D34:W34,"NC") -> 0 | Z34: =COUNTIF(D34:W34,"NA") -> 0 | AA34: =COUNTIF(D34:W34,"NT") -> 1 | AB34: =IF(Y34>0,"NC",IF(X34>0,"C",IF(AA34>0,"NT","NA"))) -> NT | AC34: 5 | AD34: =Critères!$B34 -> 5.1 | AE34: =Critères!$A34 -> TABLEAUX | AF34: ='P01'!$E31 -> N | AG34: =#REF! -> #REF! | AH34: =#REF! -> #REF! | AI34: =#REF! -> #REF! | AJ34: =#REF! -> #REF! | AK34: =#REF! -> #REF! | AL34: =#REF! -> #REF! | AM34: =#REF! -> #REF! | AN34: =#REF! -> #REF! | ... AY34: =#REF! -> #REF! | AZ34: =COUNTIF(AF34:AY34,"D") -> 0
A35: 5 | B35: =Critères!$B35 -> 5.2 | C35: =Critères!$A34 -> TABLEAUX | D35: ='P01'!$D32 -> NT | E35: =#REF! -> #REF! | F35: =#REF! -> #REF! | G35: =#REF! -> #REF! | H35: =#REF! -> #REF! | I35: =#REF! -> #REF! | J35: =#REF! -> #REF! | K35: =#REF! -> #REF! | L35: =#REF! -> #REF! | ... W35: =#REF! -> #REF! | X35: =COUNTIF(D35:W35,"C") -> 0 | Y35: =COUNTIF(D35:W35,"NC") -> 0 | Z35: =COUNTIF(D35:W35,"NA") -> 0 | AA35: =COUNTIF(D35:W35,"NT") -> 1 | AB35: =IF(Y35>0,"NC",IF(X35>0,"C",IF(AA35>0,"NT","NA"))) -> NT | AC35: 5 | AD35: =Critères!$B35 -> 5.2 | AE35: =Critères!$A34 -> TABLEAUX | AF35: ='P01'!$E32 -> N | AG35: =#REF! -> #REF! | AH35: =#REF! -> #REF! | AI35: =#REF! -> #REF! | AJ35: =#REF! -> #REF! | AK35: =#REF! -> #REF! | AL35: =#REF! -> #REF! | AM35: =#REF! -> #REF! | AN35: =#REF! -> #REF! | ... AY35: =#REF! -> #REF! | AZ35: =COUNTIF(AF35:AY35,"D") -> 0
A36: 5 | B36: =Critères!$B36 -> 5.3 | C36: =Critères!$A34 -> TABLEAUX | D36: ='P01'!$D33 -> NT | E36: =#REF! -> #REF! | F36: =#REF! -> #REF! | G36: =#REF! -> #REF! | H36: =#REF! -> #REF! | I36: =#REF! -> #REF! | J36: =#REF! -> #REF! | K36: =#REF! -> #REF! | L36: =#REF! -> #REF! | ... W36: =#REF! -> #REF! | X36: =COUNTIF(D36:W36,"C") -> 0 | Y36: =COUNTIF(D36:W36,"NC") -> 0 | Z36: =COUNTIF(D36:W36,"NA") -> 0 | AA36: =COUNTIF(D36:W36,"NT") -> 1 | AB36: =IF(Y36>0,"NC",IF(X36>0,"C",IF(AA36>0,"NT","NA"))) -> NT | AC36: 5 | AD36: =Critères!$B36 -> 5.3 | AE36: =Critères!$A34 -> TABLEAUX | AF36: ='P01'!$E33 -> N | AG36: =#REF! -> #REF! | AH36: =#REF! -> #REF! | AI36: =#REF! -> #REF! | AJ36: =#REF! -> #REF! | AK36: =#REF! -> #REF! | AL36: =#REF! -> #REF! | AM36: =#REF! -> #REF! | AN36: =#REF! -> #REF! | ... AY36: =#REF! -> #REF! | AZ36: =COUNTIF(AF36:AY36,"D") -> 0
A37: 5 | B37: =Critères!$B37 -> 5.4 | C37: =Critères!$A34 -> TABLEAUX | D37: ='P01'!$D34 -> NT | E37: =#REF! -> #REF! | F37: =#REF! -> #REF! | G37: =#REF! -> #REF! | H37: =#REF! -> #REF! | I37: =#REF! -> #REF! | J37: =#REF! -> #REF! | K37: =#REF! -> #REF! | L37: =#REF! -> #REF! | ... W37: =#REF! -> #REF! | X37: =COUNTIF(D37:W37,"C") -> 0 | Y37: =COUNTIF(D37:W37,"NC") -> 0 | Z37: =COUNTIF(D37:W37,"NA") -> 0 | AA37: =COUNTIF(D37:W37,"NT") -> 1 | AB37: =IF(Y37>0,"NC",IF(X37>0,"C",IF(AA37>0,"NT","NA"))) -> NT | AC37: 5 | AD37: =Critères!$B37 -> 5.4 | AE37: =Critères!$A34 -> TABLEAUX | AF37: ='P01'!$E34 -> N | AG37: =#REF! -> #REF! | AH37: =#REF! -> #REF! | AI37: =#REF! -> #REF! | AJ37: =#REF! -> #REF! | AK37: =#REF! -> #REF! | AL37: =#REF! -> #REF! | AM37: =#REF! -> #REF! | AN37: =#REF! -> #REF! | ... AY37: =#REF! -> #REF! | AZ37: =COUNTIF(AF37:AY37,"D") -> 0
A38: 5 | B38: =Critères!$B38 -> 5.5 | C38: =Critères!$A34 -> TABLEAUX | D38: ='P01'!$D35 -> NT | E38: =#REF! -> #REF! | F38: =#REF! -> #REF! | G38: =#REF! -> #REF! | H38: =#REF! -> #REF! | I38: =#REF! -> #REF! | J38: =#REF! -> #REF! | K38: =#REF! -> #REF! | L38: =#REF! -> #REF! | ... W38: =#REF! -> #REF! | X38: =COUNTIF(D38:W38,"C") -> 0 | Y38: =COUNTIF(D38:W38,"NC") -> 0 | Z38: =COUNTIF(D38:W38,"NA") -> 0 | AA38: =COUNTIF(D38:W38,"NT") -> 1 | AB38: =IF(Y38>0,"NC",IF(X38>0,"C",IF(AA38>0,"NT","NA"))) -> NT | AC38: 5 | AD38: =Critères!$B38 -> 5.5 | AE38: =Critères!$A34 -> TABLEAUX | AF38: ='P01'!$E35 -> N | AG38: =#REF! -> #REF! | AH38: =#REF! -> #REF! | AI38: =#REF! -> #REF! | AJ38: =#REF! -> #REF! | AK38: =#REF! -> #REF! | AL38: =#REF! -> #REF! | AM38: =#REF! -> #REF! | AN38: =#REF! -> #REF! | ... AY38: =#REF! -> #REF! | AZ38: =COUNTIF(AF38:AY38,"D") -> 0
A39: 5 | B39: =Critères!$B39 -> 5.6 | C39: =Critères!$A34 -> TABLEAUX | D39: ='P01'!$D36 -> NT | E39: =#REF! -> #REF! | F39: =#REF! -> #REF! | G39: =#REF! -> #REF! | H39: =#REF! -> #REF! | I39: =#REF! -> #REF! | J39: =#REF! -> #REF! | K39: =#REF! -> #REF! | L39: =#REF! -> #REF! | ... W39: =#REF! -> #REF! | X39: =COUNTIF(D39:W39,"C") -> 0 | Y39: =COUNTIF(D39:W39,"NC") -> 0 | Z39: =COUNTIF(D39:W39,"NA") -> 0 | AA39: =COUNTIF(D39:W39,"NT") -> 1 | AB39: =IF(Y39>0,"NC",IF(X39>0,"C",IF(AA39>0,"NT","NA"))) -> NT | AC39: 5 | AD39: =Critères!$B39 -> 5.6 | AE39: =Critères!$A34 -> TABLEAUX | AF39: ='P01'!$E36 -> N | AG39: =#REF! -> #REF! | AH39: =#REF! -> #REF! | AI39: =#REF! -> #REF! | AJ39: =#REF! -> #REF! | AK39: =#REF! -> #REF! | AL39: =#REF! -> #REF! | AM39: =#REF! -> #REF! | AN39: =#REF! -> #REF! | ... AY39: =#REF! -> #REF! | AZ39: =COUNTIF(AF39:AY39,"D") -> 0
A40: 5 | B40: =Critères!$B40 -> 5.7 | C40: =Critères!$A34 -> TABLEAUX | D40: ='P01'!$D37 -> NT | E40: =#REF! -> #REF! | F40: =#REF! -> #REF! | G40: =#REF! -> #REF! | H40: =#REF! -> #REF! | I40: =#REF! -> #REF! | J40: =#REF! -> #REF! | K40: =#REF! -> #REF! | L40: =#REF! -> #REF! | ... W40: =#REF! -> #REF! | X40: =COUNTIF(D40:W40,"C") -> 0 | Y40: =COUNTIF(D40:W40,"NC") -> 0 | Z40: =COUNTIF(D40:W40,"NA") -> 0 | AA40: =COUNTIF(D40:W40,"NT") -> 1 | AB40: =IF(Y40>0,"NC",IF(X40>0,"C",IF(AA40>0,"NT","NA"))) -> NT | AC40: 5 | AD40: =Critères!$B40 -> 5.7 | AE40: =Critères!$A34 -> TABLEAUX | AF40: ='P01'!$E37 -> N | AG40: =#REF! -> #REF! | AH40: =#REF! -> #REF! | AI40: =#REF! -> #REF! | AJ40: =#REF! -> #REF! | AK40: =#REF! -> #REF! | AL40: =#REF! -> #REF! | AM40: =#REF! -> #REF! | AN40: =#REF! -> #REF! | ... AY40: =#REF! -> #REF! | AZ40: =COUNTIF(AF40:AY40,"D") -> 0
A41: 5 | B41: =Critères!$B41 -> 5.8 | C41: =Critères!$A34 -> TABLEAUX | D41: ='P01'!$D38 -> NT | E41: =#REF! -> #REF! | F41: =#REF! -> #REF! | G41: =#REF! -> #REF! | H41: =#REF! -> #REF! | I41: =#REF! -> #REF! | J41: =#REF! -> #REF! | K41: =#REF! -> #REF! | L41: =#REF! -> #REF! | ... W41: =#REF! -> #REF! | X41: =COUNTIF(D41:W41,"C") -> 0 | Y41: =COUNTIF(D41:W41,"NC") -> 0 | Z41: =COUNTIF(D41:W41,"NA") -> 0 | AA41: =COUNTIF(D41:W41,"NT") -> 1 | AB41: =IF(Y41>0,"NC",IF(X41>0,"C",IF(AA41>0,"NT","NA"))) -> NT | AC41: 5 | AD41: =Critères!$B41 -> 5.8 | AE41: =Critères!$A34 -> TABLEAUX | AF41: ='P01'!$E38 -> N | AG41: =#REF! -> #REF! | AH41: =#REF! -> #REF! | AI41: =#REF! -> #REF! | AJ41: =#REF! -> #REF! | AK41: =#REF! -> #REF! | AL41: =#REF! -> #REF! | AM41: =#REF! -> #REF! | AN41: =#REF! -> #REF! | ... AY41: =#REF! -> #REF! | AZ41: =COUNTIF(AF41:AY41,"D") -> 0
...

Sheet P01
A1: =#REF! -> #REF!
A2: =CONCATENATE(#REF!," : ",#REF!) -> #REF!
A3: Thématique | B3: Critère | C3: Recommandation | D3: Statut | E3: Dérogation | F3: Modifications à apporter | G3: Commentaires en cas de dérogations
A4: =Critères!$A$3 -> IMAGES | B4: =Critères!B3 -> 1.1 | C4: =Critères!C3 -> Chaque image porteuse d’information a-t-elle une alternative textuelle ? | D4: NT | E4: N
B5: =Critères!B4 -> 1.2 | C5: =Critères!C4 -> Chaque image de décoration est-elle correctement ignorée par les technologies d’assistance ? | D5: NT | E5: N
B6: =Critères!B5 -> 1.3 | C6: =Critères!C5 -> Pour chaque image porteuse d'information ayant une alternative textuelle, cette alternative est-elle pertinente (hors cas particuliers) ? | D6: NT | E6: N
B7: =Critères!B6 -> 1.4 | C7: =Critères!C6 -> Pour chaque image utilisée comme CAPTCHA ou comme image-test, ayant une alternative textuelle, cette alternative permet-elle d’identifier la nature et la fonction de l’image ? | D7: NT | E7: N
B8: =Critères!B7 -> 1.5 | C8: =Critères!C7 -> Pour chaque image utilisée comme CAPTCHA, une solution d’accès alternatif au contenu ou à la fonction du CAPTCHA est-elle présente ? | D8: NT | E8: N
B9: =Critères!B8 -> 1.6 | C9: =Critères!C8 -> Chaque image porteuse d’information a-t-elle, si nécessaire, une description détaillée ? | D9: NT | E9: N
B10: =Critères!B9 -> 1.7 | C10: =Critères!C9 -> Pour chaque image porteuse d’information ayant une description détaillée, cette description est-elle pertinente ? | D10: NT | E10: N
B11: =Critères!B10 -> 1.8 | C11: =Critères!C10 -> Chaque image texte porteuse d’information, en l’absence d’un mécanisme de remplacement, doit si possible être remplacée par du texte stylé. Cette règle est-elle respectée (hors cas particuliers) ? | D11: NT | E11: N
B12: =Critères!B11 -> 1.9 | C12: =Critères!C11 -> Chaque légende d’image est-elle, si nécessaire, correctement reliée à l’image correspondante ? | D12: NT | E12: N
A13: =Critères!$A$13 -> CADRES | B13: =Critères!B13 -> 2.1 | C13: =Critères!C13 -> Chaque cadre a-t-il un titre de cadre ? | D13: NT | E13: N
B14: =Critères!B14 -> 2.2 | C14: =Critères!C14 -> Pour chaque cadre ayant un titre de cadre, ce titre de cadre est-il pertinent ? | D14: NT | E14: N
A15: =Critères!$A$16 -> COULEURS | B15: =Critères!B16 -> 3.1 | C15: =Critères!C16 -> Dans chaque page web, l’information ne doit pas être donnée uniquement par la couleur. Cette règle est-elle respectée ? | D15: NT | E15: N
B16: =Critères!B17 -> 3.2 | C16: =Critères!C17 -> Dans chaque page web, le contraste entre la couleur du texte et la couleur de son arrière-plan est-il suffisamment élevé (hors cas particuliers) ? | D16: NT | E16: N
B17: =Critères!B18 -> 3.3 | C17: =Critères!C18 -> Dans chaque page web, les couleurs utilisées dans les composants d’interface ou les éléments graphiques porteurs d’informations sont-elles suffisamment contrastées (hors cas particuliers) ? | D17: NT | E17: N
A18: =Critères!$A$20 -> MULTIMÉDIA | B18: =Critères!B20 -> 4.1 | C18: =Critères!C20 -> Chaque média temporel pré-enregistré a-t-il, si nécessaire, une transcription textuelle ou une audiodescription (hors cas particuliers) ? | D18: NT | E18: N
B19: =Critères!B21 -> 4.2 | C19: =Critères!C21 -> Pour chaque média temporel pré-enregistré ayant une transcription textuelle ou une audiodescription synchronisée, celles-ci sont-elles pertinentes (hors cas particuliers) ? | D19: NT | E19: N
B20: =Critères!B22 -> 4.3 | C20: =Critères!C22 -> Chaque média temporel synchronisé pré-enregistré a-t-il, si nécessaire, des sous-titres synchronisés (hors cas particuliers) ? | D20: NT | E20: N
B21: =Critères!B23 -> 4.4 | C21: =Critères!C23 -> Pour chaque média temporel synchronisé pré-enregistré ayant des sous-titres synchronisés, ces sous-titres sont-ils pertinents ? | D21: NT | E21: N
B22: =Critères!B24 -> 4.5 | C22: =Critères!C24 -> Chaque média temporel pré-enregistré a-t-il, si nécessaire, une audiodescription synchronisée (hors cas particuliers) ? | D22: NT | E22: N
B23: =Critères!B25 -> 4.6 | C23: =Critères!C25 -> Pour chaque média temporel pré-enregistré ayant une audiodescription synchronisée, celle-ci est-elle pertinente ? | D23: NT | E23: N
B24: =Critères!B26 -> 4.7 | C24: =Critères!C26 -> Chaque média temporel est-il clairement identifiable (hors cas particuliers) ? | D24: NT | E24: N
B25: =Critères!B27 -> 4.8 | C25: =Critères!C27 -> Chaque média non temporel a-t-il, si nécessaire, une alternative (hors cas particuliers) ? | D25: NT | E25: N
B26: =Critères!B28 -> 4.9 | C26: =Critères!C28 -> Pour chaque média non temporel ayant une alternative, cette alternative est-elle pertinente ? | D26: NT | E26: N
B27: =Critères!B29 -> 4.10 | C27: =Critères!C29 -> Chaque son déclenché automatiquement est-il contrôlable par l’utilisateur ? | D27: NT | E27: N
B28: =Critères!B30 -> 4.11 | C28: =Critères!C30 -> La consultation de chaque média temporel est-elle, si nécessaire, contrôlable par le clavier et tout dispositif de pointage ? | D28: NT | E28: N
B29: =Critères!B31 -> 4.12 | C29: =Critères!C31 -> La consultation de chaque média non temporel est-elle contrôlable par le clavier et tout dispositif de pointage ? | D29: NT | E29: N
B30: =Critères!B32 -> 4.13 | C30: =Critères!C32 -> Chaque média temporel et non temporel est-il compatible avec les technologies d’assistance (hors cas particuliers) ? | D30: NT | E30: N
A31: =Critères!$A$34 -> TABLEAUX | B31: =Critères!B34 -> 5.1 | C31: =Critères!C34 -> Chaque tableau de données complexe a-t-il un résumé ? | D31: NT | E31: N
B32: =Critères!B35 -> 5.2 | C32: =Critères!C35 -> Pour chaque tableau de données complexe ayant un résumé, celui-ci est-il pertinent ? | D32: NT | E32: N
B33: =Critères!B36 -> 5.3 | C33: =Critères!C36 -> Pour chaque tableau de mise en forme, le contenu linéarisé reste-t-il compréhensible ? | D33: NT | E33: N
B34: =Critères!B37 -> 5.4 | C34: =Critères!C37 -> Pour chaque tableau de données ayant un titre, le titre est-il correctement associé au tableau de données ? | D34: NT | E34: N
B35: =Critères!B38 -> 5.5 | C35: =Critères!C38 -> Pour chaque tableau de données ayant un titre, celui-ci est-il pertinent ? | D35: NT | E35: N
B36: =Critères!B39 -> 5.6 | C36: =Critères!C39 -> Pour chaque tableau de données, chaque en-tête de colonnes et chaque en-tête de lignes sont-ils correctement déclarés ? | D36: NT | E36: N
B37: =Critères!B40 -> 5.7 | C37: =Critères!C40 -> Pour chaque tableau de données, la technique appropriée permettant d’associer chaque cellule avec ses en-têtes est-elle utilisée (hors cas particuliers) ? | D37: NT | E37: N
B38: =Critères!B41 -> 5.8 | C38: =Critères!C41 -> Chaque tableau de mise en forme ne doit pas utiliser d’éléments propres aux tableaux de données. Cette règle est-elle respectée ? | D38: NT | E38: N
A39: =Critères!$A$43 -> LIENS | B39: =Critères!B43 -> 6.1 | C39: =Critères!C43 -> Chaque lien est-il explicite (hors cas particuliers) ? | D39: NT | E39: N
B40: =Critères!B44 -> 6.2 | C40: =Critères!C44 -> Dans chaque page web, chaque lien a-t-il un intitulé ? | D40: NT | E40: N
...
